<?xml version="1.0"?>
  <robot name="smr">
    <link name="base_link">
      <visual>
        <geometry>
          <cylinder length="0.165" radius="0.33"/>
        </geometry>
        <origin rpy="0 0 0" xyz="0.0 0 0.1"/>
	<material name="gray">
        	<color rgba="0.5 0.5 0.5 1"/>
        </material>
      </visual>
    </link>

    <link name="base_scan">
      <visual>
        <geometry>
          <box size="0.15 .15 .3"/>
        </geometry>
        <origin rpy="0 0 0" xyz="0.075 0.0 0.15"/>
	<material name="blue">
        	<color rgba="0.1 0.1 0.5 1"/>
        </material>
      </visual>
    </link>

    <joint name="base_to_scan" type="fixed">
    	<parent link="base_link"/>
    	<child link="base_scan"/>
    	<origin xyz="0.2 0 0.185"/>
    </joint>


    <link name="laser">
      <visual>
        <geometry>
          <box size="0 0 0"/>
        </geometry>
        <origin rpy="0 0 0" xyz="0 0 0"/>
	<material name="gray">
        	<color rgba="0.1 0.1 0.5 1"/>
        </material>
      </visual>
    </link>

    <joint name="scan_to_laser" type="fixed">
    	<parent link="base_scan"/>
    	<child link="laser"/>
    	<origin rpy="0 0 0" xyz="0 0 0"/> <!-- Modifiy "R" to mirror laser scan if necessary -->
    </joint>


    <link name="wheel_R">
      <visual>
        <geometry>
          <cylinder length="0.05" radius="0.1"/>
        </geometry>
        <origin rpy="1.57 0 0" xyz="0 0 0"/>
        <material name="black"/>
      </visual>
    </link>

    <joint name="base_to_wheelR" type="continuous">
      <parent link="base_link"/>
      <child link="wheel_R"/>
      <origin xyz="0.00 -0.25 0.1"/>
    </joint>

     <link name="wheel_L">
      <visual>
        <geometry>
          <cylinder length="0.05" radius="0.1"/>
        </geometry>
        <origin rpy="1.57 0 0" xyz="0 0 0"/>
        <material name="black"/>
      </visual>
    </link>

    <joint name="base_to_wheelL" type="continuous">
      <parent link="base_link"/>
      <child link="wheel_L"/>
      <origin xyz="0.00 0.25 0.1"/>
    </joint>


  <link name="lower_torso">
      <visual>
        <geometry>
          <box size="0.4 0.4 .22"/>
        </geometry>
        <origin rpy="0 0 0" xyz="0 0 0.11"/>
        <material name="gray">
        	<color rgba="0.5 0.5 0.5 1"/>
        </material>
      </visual>
    </link>

    <joint name="lower_torso_to_base" type="fixed">
    	<parent link="base_link"/>
    	<child link="lower_torso"/>
    	<origin xyz="0.0 0 0.185"/>
    </joint>


  <link name="upper_torso">
      <visual>
        <geometry>
          <box size="0.27 0.27 .34"/>
        </geometry>
        <origin rpy="0 0 0" xyz="0 0 0.17"/>
        <material name="gray">
        	<color rgba="0.5 0.5 0.5 1"/>
        </material>
      </visual>
    </link>

    <joint name="upper_torso_to_lower_torso" type="fixed">
    	<parent link="lower_torso"/>
    	<child link="upper_torso"/>
    	<origin xyz="0.0 0 0.22"/>
    </joint>


     <link name="head_disk">
      <visual>
        <geometry>
          <cylinder length="0.01" radius="0.18"/>
        </geometry>
        <origin rpy="0 0 0" xyz="0 0 0.01"/>
        <material name="blue"/>
      </visual>
    </link>

    <joint name="head_disk_to_upper_torso" type="fixed">
      <parent link="upper_torso"/>
      <child link="head_disk"/>
      <origin xyz="0.00 0 0.34"/>
    </joint>


    <link name="kinect_support">
      <visual>
        <geometry>
          <box size="0.03 0.03 1.0"/>
        </geometry>
        <origin rpy="0 0 0" xyz="0 0 0.135"/>
        <material name="gray"/>
      </visual>
    </link>

    <joint name="support_to_head_disk" type="fixed">
      <parent link="head_disk"/>
      <child link="kinect_support"/>
      <origin xyz="0 0 0.01"/>
    </joint>


   <link name="camera_link_fake">
  <visual>
    <geometry>
      <box size="0.064 0.121 0.0381" />
    </geometry>
    <origin rpy="0 0 0" xyz="0 0 0"/>
    <material name="Blue" />
  </visual>
  <inertial>
      <mass value="0.0001" />
      <origin xyz="0 0 0" />
      <inertia ixx="0.0001" ixy="0.0" ixz="0.0"
               iyy="0.0001" iyz="0.0" 
               izz="0.0001" />
  </inertial>
</link>

<joint name="support_to_kinect" type="fixed">
      <parent link="kinect_support"/>
      <child link="camera_link_fake"/>
      <origin rpy="0 0.34 0" xyz="0.03 0 0.65"/>
    </joint>


<!--

<link name="camera_depth_frame">
  <inertial>
      <mass value="0.0001" />
      <origin xyz="0 0 0" />
      <inertia ixx="0.0001" ixy="0.0" ixz="0.0"
               iyy="0.0001" iyz="0.0" 
               izz="0.0001" />
  </inertial>
</link>

<joint name="kinect_depth_joint" type="fixed">
  <origin xyz="0 0.028 0" rpy="0 0 0" />
  <parent link="camera_link" />
  <child link="camera_depth_frame" />
</joint>


<link name="camera_depth_optical_frame">
  <inertial>
      <mass value="0.0001" />
      <origin xyz="0 0 0" />
      <inertia ixx="0.0001" ixy="0.0" ixz="0.0"
               iyy="0.0001" iyz="0.0" 
               izz="0.0001" />
  </inertial>
</link>

<joint name="depth_optical_joint" type="fixed">
  <origin xyz="0 0 0" rpy="1.57 0 1.57" />
  <parent link="camera_depth_frame" />
  <child link="camera_depth_optical_frame" />
</joint>
-->

    
  </robot>
